<?xml version="1.0" encoding="utf-8"?>
<!-- This URDF was automatically created by SolidWorks to URDF Exporter! Originally created by Stephen Brawner (brawner@gmail.com) 
     Commit Version: 1.6.0-4-g7f85cfe  Build Version: 1.6.7995.38578
     For more information, please see http://wiki.ros.org/sw_urdf_exporter -->
<robot
  name="one_wheel_cubli">
  <link
    name="base_link">
    <inertial>
      <origin
        xyz="0 0 0.1114"
        rpy="0 0 0" />
      <mass
        value="0.59044" />
      <inertia
        ixx="0.009253"
        ixy="0"
        ixz="0"
        iyy="0.019863"
        iyz="0"
        izz="0.011663" />
    </inertial>
    <visual>
      <origin
        xyz="0 0 0"
        rpy="0 0 0" />
      <geometry>
        <mesh
          filename="../meshes/base_link.STL" />
      </geometry>
      <material
        name="">
        <color
          rgba="1 1 1 1" />
      </material>
    </visual>
    <collision>
      <origin
        xyz="0 0 0"
        rpy="0 0 0" />
      <geometry>
        <mesh
          filename="../meshes/base_link.STL" />
      </geometry>
    </collision>
  </link>
  <link
    name="wheel">
    <inertial>
      <origin
        xyz="0 0 0"
        rpy="0 0 0" />
      <mass
        value="0.08" />
      <inertia
        ixx="3.145897E-05"
        ixy="0"
        ixz="0"
        iyy="3.145897E-05"
        iyz="0"
        izz="6.2588E-05" />
    </inertial>
    <visual>
      <origin
        xyz="0 0 0"
        rpy="0 0 0" />
      <geometry>
        <mesh
          filename="../meshes/wheel.STL" />
      </geometry>
      <material
        name="">
        <color
          rgba="1 1 1 1" />
      </material>
    </visual>
    <collision>
      <origin
        xyz="0 0 0"
        rpy="0 0 0" />
      <geometry>
        <mesh
          filename="../meshes/wheel.STL" />
      </geometry>
    </collision>
  </link>
  <joint
    name="wheel_joint"
    type="continuous">
    <origin
      xyz="0 0 0.1"
      rpy="-1.5708 0 -0.7854" />
    <parent
      link="base_link" />
    <child
      link="wheel" />
    <axis
      xyz="0 0 -1" />
  </joint>
</robot>